[[
  {
    "name": "symfony.request",
    "service": "test_symfony_23",
    "resource": "error",
    "trace_id": 0,
    "span_id": 1,
    "parent_id": 2772491324382070667,
    "type": "web",
    "error": 1,
    "meta": {
      "_dd.p.dm": "-0",
      "_dd.p.tid": "6660cfc900000000",
      "component": "symfony",
      "error.message": "Uncaught Exception: An exception occurred in /home/circleci/datadog/tests/Frameworks/Symfony/Version_2_3/src/AppBundle/Controller/CommonScenariosController.php:40",
      "error.stack": "#0 [internal function]: AppBundle\\Controller\\CommonScenariosController->errorAction()\n#1 /home/circleci/datadog/tests/Frameworks/Symfony/Version_2_3/app/bootstrap.php.cache(2978): call_user_func_array()\n#2 /home/circleci/datadog/tests/Frameworks/Symfony/Version_2_3/app/bootstrap.php.cache(2952): Symfony\\Component\\HttpKernel\\HttpKernel->handleRaw()\n#3 /home/circleci/datadog/tests/Frameworks/Symfony/Version_2_3/app/bootstrap.php.cache(3081): Symfony\\Component\\HttpKernel\\HttpKernel->handle()\n#4 /home/circleci/datadog/tests/Frameworks/Symfony/Version_2_3/app/bootstrap.php.cache(2351): Symfony\\Component\\HttpKernel\\DependencyInjection\\ContainerAwareHttpKernel->handle()\n#5 /home/circleci/datadog/tests/Frameworks/Symfony/Version_2_3/web/app.php(14): Symfony\\Component\\HttpKernel\\Kernel->handle()\n#6 {main}\n\nNext Symfony\\Component\\DependencyInjection\\Exception\\RuntimeException: You cannot set service \"request\" of inactive scope. in /home/circleci/datadog/tests/Frameworks/Symfony/Version_2_3/app/bootstrap.php.cache:1995\nStack trace:\n#0 /home/circleci/datadog/tests/Frameworks/Symfony/Version_2_3/app/bootstrap.php.cache(3087): Symfony\\Component\\DependencyInjection\\Container->set()\n#1 /home/circleci/datadog/tests/Frameworks/Symfony/Version_2_3/app/bootstrap.php.cache(2351): Symfony\\Component\\HttpKernel\\DependencyInjection\\ContainerAwareHttpKernel->handle()\n#2 /home/circleci/datadog/tests/Frameworks/Symfony/Version_2_3/web/app.php(14): Symfony\\Component\\HttpKernel\\Kernel->handle()\n#3 {main}",
      "error.type": "Exception",
      "http.method": "GET",
      "http.status_code": "200",
      "http.url": "http://localhost:9999/error?key=value&<redacted>",
      "runtime-id": "19a2c263-acf7-400d-8a02-8117eda94132",
      "span.kind": "server",
      "symfony.route.action": "AppBundle\\Controller\\CommonScenariosController@errorAction",
      "symfony.route.name": "error"
    },
    "metrics": {
      "_sampling_priority_v1": 1.0
    }
  },
     {
       "name": "symfony.httpkernel.kernel.handle",
       "service": "test_symfony_23",
       "resource": "AppKernel",
       "trace_id": 0,
       "span_id": 2,
       "parent_id": 1,
       "type": "web",
       "error": 1,
       "meta": {
         "component": "symfony",
         "error.message": "Thrown Symfony\\Component\\DependencyInjection\\Exception\\RuntimeException: You cannot set service \"request\" of inactive scope. in /home/circleci/datadog/tests/Frameworks/Symfony/Version_2_3/app/bootstrap.php.cache:1995",
         "error.stack": "#0 /home/circleci/datadog/tests/Frameworks/Symfony/Version_2_3/app/bootstrap.php.cache(3087): Symfony\\Component\\DependencyInjection\\Container->set()\n#1 /home/circleci/datadog/tests/Frameworks/Symfony/Version_2_3/app/bootstrap.php.cache(2351): Symfony\\Component\\HttpKernel\\DependencyInjection\\ContainerAwareHttpKernel->handle()\n#2 /home/circleci/datadog/tests/Frameworks/Symfony/Version_2_3/web/app.php(14): Symfony\\Component\\HttpKernel\\Kernel->handle()\n#3 {main}",
         "error.type": "Symfony\\Component\\DependencyInjection\\Exception\\RuntimeException",
         "span.kind": "server"
       }
     },
        {
          "name": "symfony.httpkernel.kernel.boot",
          "service": "test_symfony_23",
          "resource": "AppKernel",
          "trace_id": 0,
          "span_id": 3,
          "parent_id": 2,
          "type": "web",
          "meta": {
            "component": "symfony"
          }
        },
        {
          "name": "symfony.kernel.handle",
          "service": "test_symfony_23",
          "resource": "symfony.kernel.handle",
          "trace_id": 0,
          "span_id": 4,
          "parent_id": 2,
          "type": "web",
          "error": 1,
          "meta": {
            "component": "symfony",
            "error.message": "Thrown ArgumentCountError: array_diff_key() does not accept unknown named parameters in /home/circleci/datadog/tests/Frameworks/Symfony/Version_2_3/app/bootstrap.php.cache:2125",
            "error.stack": "#0 [internal function]: array_diff_key()\n#1 /home/circleci/datadog/tests/Frameworks/Symfony/Version_2_3/app/bootstrap.php.cache(2125): call_user_func_array()\n#2 /home/circleci/datadog/tests/Frameworks/Symfony/Version_2_3/app/bootstrap.php.cache(3078): Symfony\\Component\\DependencyInjection\\Container->enterScope()\n#3 /home/circleci/datadog/tests/Frameworks/Symfony/Version_2_3/vendor/symfony/symfony/src/Symfony/Component/HttpKernel/EventListener/ExceptionListener.php(60): Symfony\\Component\\HttpKernel\\DependencyInjection\\ContainerAwareHttpKernel->handle()\n#4 [internal function]: Symfony\\Component\\HttpKernel\\EventListener\\ExceptionListener->onKernelException()\n#5 /home/circleci/datadog/tests/Frameworks/Symfony/Version_2_3/app/cache/prod/classes.php(1691): call_user_func()\n#6 /home/circleci/datadog/tests/Frameworks/Symfony/Version_2_3/app/cache/prod/classes.php(1617): Symfony\\Component\\EventDispatcher\\EventDispatcher->doDispatch()\n#7 /home/circleci/datadog/tests/Frameworks/Symfony/Version_2_3/app/bootstrap.php.cache(3004): Symfony\\Component\\EventDispatcher\\EventDispatcher->dispatch()\n#8 /home/circleci/datadog/tests/Frameworks/Symfony/Version_2_3/app/bootstrap.php.cache(2957): Symfony\\Component\\HttpKernel\\HttpKernel->handleException()\n#9 /home/circleci/datadog/tests/Frameworks/Symfony/Version_2_3/app/bootstrap.php.cache(3081): Symfony\\Component\\HttpKernel\\HttpKernel->handle()\n#10 /home/circleci/datadog/tests/Frameworks/Symfony/Version_2_3/app/bootstrap.php.cache(2351): Symfony\\Component\\HttpKernel\\DependencyInjection\\ContainerAwareHttpKernel->handle()\n#11 /home/circleci/datadog/tests/Frameworks/Symfony/Version_2_3/web/app.php(14): Symfony\\Component\\HttpKernel\\Kernel->handle()\n#12 {main}",
            "error.type": "ArgumentCountError"
          }
        },
           {
             "name": "symfony.kernel.request",
             "service": "test_symfony_23",
             "resource": "symfony.kernel.request",
             "trace_id": 0,
             "span_id": 5,
             "parent_id": 4,
             "type": "web",
             "meta": {
               "component": "symfony"
             }
           },
           {
             "name": "symfony.kernel.controller",
             "service": "test_symfony_23",
             "resource": "symfony.kernel.controller",
             "trace_id": 0,
             "span_id": 6,
             "parent_id": 4,
             "type": "web",
             "meta": {
               "component": "symfony"
             }
           },
           {
             "name": "symfony.controller",
             "service": "test_symfony_23",
             "resource": "AppBundle\\Controller\\CommonScenariosController::errorAction",
             "trace_id": 0,
             "span_id": 7,
             "parent_id": 4,
             "type": "web",
             "error": 1,
             "meta": {
               "component": "symfony",
               "error.message": "Thrown Exception: An exception occurred in /home/circleci/datadog/tests/Frameworks/Symfony/Version_2_3/src/AppBundle/Controller/CommonScenariosController.php:40",
               "error.stack": "#0 [internal function]: AppBundle\\Controller\\CommonScenariosController->errorAction()\n#1 /home/circleci/datadog/tests/Frameworks/Symfony/Version_2_3/app/bootstrap.php.cache(2978): call_user_func_array()\n#2 /home/circleci/datadog/tests/Frameworks/Symfony/Version_2_3/app/bootstrap.php.cache(2952): Symfony\\Component\\HttpKernel\\HttpKernel->handleRaw()\n#3 /home/circleci/datadog/tests/Frameworks/Symfony/Version_2_3/app/bootstrap.php.cache(3081): Symfony\\Component\\HttpKernel\\HttpKernel->handle()\n#4 /home/circleci/datadog/tests/Frameworks/Symfony/Version_2_3/app/bootstrap.php.cache(2351): Symfony\\Component\\HttpKernel\\DependencyInjection\\ContainerAwareHttpKernel->handle()\n#5 /home/circleci/datadog/tests/Frameworks/Symfony/Version_2_3/web/app.php(14): Symfony\\Component\\HttpKernel\\Kernel->handle()\n#6 {main}",
               "error.type": "Exception"
             }
           },
           {
             "name": "symfony.kernel.handleException",
             "service": "test_symfony_23",
             "resource": "symfony.kernel.handleException",
             "trace_id": 0,
             "span_id": 8,
             "parent_id": 4,
             "type": "web",
             "error": 1,
             "meta": {
               "component": "symfony",
               "error.message": "Thrown ArgumentCountError: array_diff_key() does not accept unknown named parameters in /home/circleci/datadog/tests/Frameworks/Symfony/Version_2_3/app/bootstrap.php.cache:2125",
               "error.stack": "#0 [internal function]: array_diff_key()\n#1 /home/circleci/datadog/tests/Frameworks/Symfony/Version_2_3/app/bootstrap.php.cache(2125): call_user_func_array()\n#2 /home/circleci/datadog/tests/Frameworks/Symfony/Version_2_3/app/bootstrap.php.cache(3078): Symfony\\Component\\DependencyInjection\\Container->enterScope()\n#3 /home/circleci/datadog/tests/Frameworks/Symfony/Version_2_3/vendor/symfony/symfony/src/Symfony/Component/HttpKernel/EventListener/ExceptionListener.php(60): Symfony\\Component\\HttpKernel\\DependencyInjection\\ContainerAwareHttpKernel->handle()\n#4 [internal function]: Symfony\\Component\\HttpKernel\\EventListener\\ExceptionListener->onKernelException()\n#5 /home/circleci/datadog/tests/Frameworks/Symfony/Version_2_3/app/cache/prod/classes.php(1691): call_user_func()\n#6 /home/circleci/datadog/tests/Frameworks/Symfony/Version_2_3/app/cache/prod/classes.php(1617): Symfony\\Component\\EventDispatcher\\EventDispatcher->doDispatch()\n#7 /home/circleci/datadog/tests/Frameworks/Symfony/Version_2_3/app/bootstrap.php.cache(3004): Symfony\\Component\\EventDispatcher\\EventDispatcher->dispatch()\n#8 /home/circleci/datadog/tests/Frameworks/Symfony/Version_2_3/app/bootstrap.php.cache(2957): Symfony\\Component\\HttpKernel\\HttpKernel->handleException()\n#9 /home/circleci/datadog/tests/Frameworks/Symfony/Version_2_3/app/bootstrap.php.cache(3081): Symfony\\Component\\HttpKernel\\HttpKernel->handle()\n#10 /home/circleci/datadog/tests/Frameworks/Symfony/Version_2_3/app/bootstrap.php.cache(2351): Symfony\\Component\\HttpKernel\\DependencyInjection\\ContainerAwareHttpKernel->handle()\n#11 /home/circleci/datadog/tests/Frameworks/Symfony/Version_2_3/web/app.php(14): Symfony\\Component\\HttpKernel\\Kernel->handle()\n#12 {main}",
               "error.type": "ArgumentCountError"
             }
           },
              {
                "name": "symfony.kernel.exception",
                "service": "test_symfony_23",
                "resource": "symfony.kernel.exception",
                "trace_id": 0,
                "span_id": 9,
                "parent_id": 8,
                "type": "web",
                "error": 1,
                "meta": {
                  "component": "symfony",
                  "error.message": "Thrown ArgumentCountError: array_diff_key() does not accept unknown named parameters in /home/circleci/datadog/tests/Frameworks/Symfony/Version_2_3/app/bootstrap.php.cache:2125",
                  "error.stack": "#0 [internal function]: array_diff_key()\n#1 /home/circleci/datadog/tests/Frameworks/Symfony/Version_2_3/app/bootstrap.php.cache(2125): call_user_func_array()\n#2 /home/circleci/datadog/tests/Frameworks/Symfony/Version_2_3/app/bootstrap.php.cache(3078): Symfony\\Component\\DependencyInjection\\Container->enterScope()\n#3 /home/circleci/datadog/tests/Frameworks/Symfony/Version_2_3/vendor/symfony/symfony/src/Symfony/Component/HttpKernel/EventListener/ExceptionListener.php(60): Symfony\\Component\\HttpKernel\\DependencyInjection\\ContainerAwareHttpKernel->handle()\n#4 [internal function]: Symfony\\Component\\HttpKernel\\EventListener\\ExceptionListener->onKernelException()\n#5 /home/circleci/datadog/tests/Frameworks/Symfony/Version_2_3/app/cache/prod/classes.php(1691): call_user_func()\n#6 /home/circleci/datadog/tests/Frameworks/Symfony/Version_2_3/app/cache/prod/classes.php(1617): Symfony\\Component\\EventDispatcher\\EventDispatcher->doDispatch()\n#7 /home/circleci/datadog/tests/Frameworks/Symfony/Version_2_3/app/bootstrap.php.cache(3004): Symfony\\Component\\EventDispatcher\\EventDispatcher->dispatch()\n#8 /home/circleci/datadog/tests/Frameworks/Symfony/Version_2_3/app/bootstrap.php.cache(2957): Symfony\\Component\\HttpKernel\\HttpKernel->handleException()\n#9 /home/circleci/datadog/tests/Frameworks/Symfony/Version_2_3/app/bootstrap.php.cache(3081): Symfony\\Component\\HttpKernel\\HttpKernel->handle()\n#10 /home/circleci/datadog/tests/Frameworks/Symfony/Version_2_3/app/bootstrap.php.cache(2351): Symfony\\Component\\HttpKernel\\DependencyInjection\\ContainerAwareHttpKernel->handle()\n#11 /home/circleci/datadog/tests/Frameworks/Symfony/Version_2_3/web/app.php(14): Symfony\\Component\\HttpKernel\\Kernel->handle()\n#12 {main}",
                  "error.type": "ArgumentCountError"
                }
              }]]
